<mujoco model="OpenLoog">
  <compiler angle="radian" meshdir="meshes/" autolimits="true"/>
  <statistic meansize="0.26443" extent="2.30442" center="-0.00615689 2.01848e-06 -0.221039"/>
  <asset>
    <mesh name="base_link" file="base_link.STL"/>
    <mesh name="Link_head_yaw" file="Link_head_yaw.STL"/>
    <mesh name="Link_head_pitch" file="Link_head_pitch.STL"/>
    <mesh name="Link_arm_r_01" file="Link_arm_r_01.STL"/>
    <mesh name="Link_arm_r_02" file="Link_arm_r_02.STL"/>
    <mesh name="Link_arm_r_03" file="Link_arm_r_03.STL"/>
    <mesh name="Link_arm_r_04" file="Link_arm_r_04.STL"/>
    <mesh name="Link_arm_r_05" file="Link_arm_r_05.STL"/>
    <mesh name="Link_arm_r_06" file="Link_arm_r_06.STL"/>
    <mesh name="Link_arm_r_07" file="Link_arm_r_07.STL"/>
    <mesh name="Link_arm_l_01" file="Link_arm_l_01.STL"/>
    <mesh name="Link_arm_l_02" file="Link_arm_l_02.STL"/>
    <mesh name="Link_arm_l_03" file="Link_arm_l_03.STL"/>
    <mesh name="Link_arm_l_04" file="Link_arm_l_04.STL"/>
    <mesh name="Link_arm_l_05" file="Link_arm_l_05.STL"/>
    <mesh name="Link_arm_l_06" file="Link_arm_l_06.STL"/>
    <mesh name="Link_arm_l_07" file="Link_arm_l_07.STL"/>
    <mesh name="Link_waist_pitch" file="Link_waist_pitch.STL"/>
    <mesh name="Link_waist_roll" file="Link_waist_roll.STL"/>
    <mesh name="Link_waist_yaw" file="Link_waist_yaw.STL"/>
    <mesh name="Link_hip_r_roll" file="Link_hip_r_roll.STL"/>
    <mesh name="Link_hip_r_yaw" file="Link_hip_r_yaw.STL"/>
    <mesh name="Link_hip_r_pitch" file="Link_hip_r_pitch.STL"/>
    <mesh name="Link_knee_r_pitch" file="Link_knee_r_pitch.STL"/>
    <mesh name="Link_ankle_r_pitch" file="Link_ankle_r_pitch.STL"/>
    <mesh name="Link_ankle_r_roll" file="Link_ankle_r_roll.STL"/>
    <mesh name="Link_hip_l_roll" file="Link_hip_l_roll.STL"/>
    <mesh name="Link_hip_l_yaw" file="Link_hip_l_yaw.STL"/>
    <mesh name="Link_hip_l_pitch" file="Link_hip_l_pitch.STL"/>
    <mesh name="Link_knee_l_pitch" file="Link_knee_l_pitch.STL"/>
    <mesh name="Link_ankle_l_pitch" file="Link_ankle_l_pitch.STL"/>
    <mesh name="Link_ankle_l_roll" file="Link_ankle_l_roll.STL"/>
  </asset>
  <worldbody>
    <body name="base_link">
      <inertial pos="-0.0196835 -0.00183223 0.194168" quat="0.702677 0.707411 0.0536958 -0.054148" mass="47.487" diaginertia="5.56389 3.5602 2.25651"/>
      <joint name="floating_base_joint" type="free"/>
      <geom type="mesh" contype="0" conaffinity="0" group="1" density="0" rgba="0.75294 0.75294 0.75294 1" mesh="base_link"/>
      <geom size="0.175 0.125 0.175" pos="0 0 0.16" type="box" rgba="0.75294 0.75294 0.75294 1"/>
      <geom pos="0.009 0 0.4064" type="mesh" contype="0" conaffinity="0" group="1" density="0" rgba="0.89804 0.91765 0.92941 1" mesh="Link_head_yaw"/>
      <geom pos="0.009 -0.0346 0.4549" type="mesh" contype="0" conaffinity="0" group="1" density="0" rgba="0.69804 0.69804 0.69804 1" mesh="Link_head_pitch"/>
      <geom pos="0.004 -0.1616 0.3922" type="mesh" contype="0" conaffinity="0" group="1" density="0" rgba="0.69804 0.69804 0.69804 1" mesh="Link_arm_r_01"/>
      <geom pos="-0.038 -0.2026 0.3922" type="mesh" contype="0" conaffinity="0" group="1" density="0" rgba="0.698039 0.698039 0.698039 1" mesh="Link_arm_r_02"/>
      <geom pos="0.004 -0.3252 0.3922" type="mesh" contype="0" conaffinity="0" group="1" density="0" rgba="0.698039 0.698039 0.698039 1" mesh="Link_arm_r_03"/>
      <geom pos="0.0393 -0.5026 0.4162" type="mesh" contype="0" conaffinity="0" group="1" density="0" rgba="0.69804 0.69804 0.69804 1" mesh="Link_arm_r_04"/>
      <geom pos="0.004 -0.6061 0.3922" type="mesh" contype="0" conaffinity="0" group="1" density="0" rgba="0.69804 0.69804 0.69804 1" mesh="Link_arm_r_05"/>
      <geom pos="-0.0225 -0.8026 0.3922" type="mesh" contype="0" conaffinity="0" group="1" density="0" rgba="0.69804 0.69804 0.69804 1" mesh="Link_arm_r_06"/>
      <geom pos="0.004 -0.8026 0.424" type="mesh" contype="0" conaffinity="0" group="1" density="0" rgba="0.77647 0.75686 0.73725 1" mesh="Link_arm_r_07"/>
      <geom pos="0.004 0.1616 0.3922" type="mesh" contype="0" conaffinity="0" group="1" density="0" rgba="0.698039 0.698039 0.698039 1" mesh="Link_arm_l_01"/>
      <geom pos="0.046 0.2026 0.3922" type="mesh" contype="0" conaffinity="0" group="1" density="0" rgba="0.698039 0.698039 0.698039 1" mesh="Link_arm_l_02"/>
      <geom pos="0.004 0.3252 0.3922" type="mesh" contype="0" conaffinity="0" group="1" density="0" rgba="0.698039 0.698039 0.698039 1" mesh="Link_arm_l_03"/>
      <geom pos="-0.0313 0.5026 0.4162" type="mesh" contype="0" conaffinity="0" group="1" density="0" rgba="0.698039 0.698039 0.698039 1" mesh="Link_arm_l_04"/>
      <geom pos="0.004 0.6061 0.3922" type="mesh" contype="0" conaffinity="0" group="1" density="0" rgba="0.69804 0.69804 0.69804 1" mesh="Link_arm_l_05"/>
      <geom pos="0.0305 0.8026 0.3922" type="mesh" contype="0" conaffinity="0" group="1" density="0" rgba="0.698039 0.698039 0.698039 1" mesh="Link_arm_l_06"/>
      <geom pos="0.0305 0.8026 0.3922" type="mesh" rgba="0.698039 0.698039 0.698039 1" mesh="Link_arm_l_06"/>
      <geom pos="0.004 0.8026 0.424" type="mesh" contype="0" conaffinity="0" group="1" density="0" rgba="0.77647 0.75686 0.73725 1" mesh="Link_arm_l_07"/>
      <geom pos="0 -0.0655 0" type="mesh" contype="0" conaffinity="0" group="1" density="0" rgba="0.69804 0.69804 0.69804 1" mesh="Link_waist_pitch"/>
      <geom pos="-0.064 0 0" type="mesh" contype="0" conaffinity="0" group="1" density="0" rgba="0.8902 0.8902 0.91373 1" mesh="Link_waist_roll"/>
      <geom pos="0.0035 0 -0.098" type="mesh" contype="0" conaffinity="0" group="1" density="0" rgba="0.8902 0.8902 0.91373 1" mesh="Link_waist_yaw"/>
      <geom pos="0.0035 0 -0.098" type="mesh" rgba="0.8902 0.8902 0.91373 1" mesh="Link_waist_yaw"/>
      <body name="Link_hip_r_roll" pos="-0.084 -0.12 -0.167">
        <inertial pos="0.075725 -0.0010616 0.016591" quat="0.611438 0.357571 0.363289 0.605233" mass="2.4334" diaginertia="0.00450678 0.00399625 0.00360607"/>
        <joint name="J_hip_r_roll" pos="0 0 0" axis="1 0 0" range="-0.17453 0.43633"/>
        <geom type="mesh" contype="0" conaffinity="0" group="1" density="0" rgba="0.89804 0.91765 0.92941 1" mesh="Link_hip_r_roll"/>
        <geom type="mesh" rgba="0.89804 0.91765 0.92941 1" mesh="Link_hip_r_roll"/>
        <body name="Link_hip_r_yaw" pos="0.08225 0 -0.01">
          <inertial pos="-3.0911e-08 -0.0071356 -0.10063" quat="0.706536 -0.0284037 0.0284037 0.706536" mass="3.4303" diaginertia="0.0080901 0.0077365 0.0066316"/>
          <joint name="J_hip_r_yaw" pos="0 0 0" axis="0 0 1" range="-0.69813 0.69813"/>
          <geom type="mesh" contype="0" conaffinity="0" group="1" density="0" rgba="0.89804 0.91765 0.92941 1" mesh="Link_hip_r_yaw"/>
          <geom type="mesh" rgba="0.89804 0.91765 0.92941 1" mesh="Link_hip_r_yaw"/>
          <body name="Link_hip_r_pitch" pos="0 0.03675 -0.1055" quat="0.980067 0 -0.198669 0">
            <inertial pos="0.0010856 -0.05497 -0.14535" quat="0.999574 0.0167987 -0.0132686 -0.0198624" mass="5.2378" diaginertia="0.0434867 0.0378166 0.0151377"/>
            <joint name="J_hip_r_pitch" pos="0 0 0" axis="0 -1 0" range="-0.7854 1.8326"/>
            <geom type="mesh" contype="0" conaffinity="0" group="1" density="0" rgba="0.69804 0.69804 0.69804 1" mesh="Link_hip_r_pitch"/>
            <geom type="mesh" rgba="0.69804 0.69804 0.69804 1" mesh="Link_hip_r_pitch"/>
            <body name="Link_knee_r_pitch" pos="0 -0.01125 -0.4" quat="0.921061 0 0.389418 0">
              <inertial pos="-0.0096425 2.9338e-06 -0.13601" quat="0.646651 -0.000144685 -0.016567 0.762606" mass="2.9775" diaginertia="0.024207 0.0238608 0.00228446"/>
              <joint name="J_knee_r_pitch" pos="0 0 0" axis="0 -1 0" range="-2.35619 0.08727"/>
              <geom type="mesh" contype="0" conaffinity="0" group="1" density="0" rgba="0.66667 0.69804 0.76863 1" mesh="Link_knee_r_pitch"/>
              <geom type="mesh" rgba="0.66667 0.69804 0.76863 1" mesh="Link_knee_r_pitch"/>
              <body name="Link_ankle_r_pitch" pos="0 0 -0.387" quat="0.980067 0 -0.198669 0">
                <inertial pos="-6.1835e-12 -1.2655e-07 -2.4682e-08" quat="0.707107 0.707107 0 0" mass="0.10145" diaginertia="2.7175e-05 2.6565e-05 6.1118e-06"/>
                <joint name="J_ankle_r_pitch" pos="0 0 0" axis="0 -1 0" range="-0.47 0.87"/>
                <geom type="mesh" contype="0" conaffinity="0" group="1" density="0" rgba="0.52941 0.54902 0.54902 1" mesh="Link_ankle_r_pitch"/>
                <geom type="mesh" rgba="0.52941 0.54902 0.54902 1" mesh="Link_ankle_r_pitch"/>
                <body name="Link_ankle_r_roll">
                  <inertial pos="0.041078 -8.9152e-08 -0.043909" quat="0 0.735951 0 0.677035" mass="0.75229" diaginertia="0.00365937 0.0036465 0.000416828"/>
                  <joint name="J_ankle_r_roll" pos="0 0 0" axis="1 0 0" range="-0.43633 0.43633"/>
                  <geom type="mesh" contype="0" conaffinity="0" group="1" density="0" rgba="0.89804 0.91765 0.92941 1" mesh="Link_ankle_r_roll"/>
                  <geom type="mesh" rgba="0.89804 0.91765 0.92941 1" mesh="Link_ankle_r_roll"/>
                </body>
              </body>
            </body>
          </body>
        </body>
      </body>
      <body name="Link_hip_l_roll" pos="-0.084 0.12 -0.167">
        <inertial pos="0.075725 -0.00093843 0.016591" quat="0.572176 0.411639 0.40134 0.584888" mass="2.4334" diaginertia="0.00425705 0.00397474 0.0033778"/>
        <joint name="J_hip_l_roll" pos="0 0 0" axis="1 0 0" range="-0.17453 0.43633"/>
        <geom type="mesh" contype="0" conaffinity="0" group="1" density="0" rgba="0.89804 0.91765 0.92941 1" mesh="Link_hip_l_roll"/>
        <geom type="mesh" rgba="0.89804 0.91765 0.92941 1" mesh="Link_hip_l_roll"/>
        <body name="Link_hip_l_yaw" pos="0.08225 0 -0.01">
          <inertial pos="-3.1716e-08 0.0071358 -0.10063" quat="0.706536 0.0284018 -0.0284018 0.706536" mass="3.4304" diaginertia="0.0080901 0.0077365 0.0066315"/>
          <joint name="J_hip_l_yaw" pos="0 0 0" axis="0 0 1" range="-0.69813 0.69813"/>
          <geom type="mesh" contype="0" conaffinity="0" group="1" density="0" rgba="0.89804 0.91765 0.92941 1" mesh="Link_hip_l_yaw"/>
          <geom type="mesh" rgba="0.89804 0.91765 0.92941 1" mesh="Link_hip_l_yaw"/>
          <body name="Link_hip_l_pitch" pos="0 -0.03675 -0.1055" quat="0.980067 0 -0.198669 0">
            <inertial pos="0.0010856 0.05497 -0.14535" quat="0.999573 -0.0167988 -0.0132685 0.0198712" mass="5.2378" diaginertia="0.0434867 0.0378166 0.0151377"/>
            <joint name="J_hip_l_pitch" pos="0 0 0" axis="0 -1 0" range="-0.7854 1.8326"/>
            <geom type="mesh" contype="0" conaffinity="0" group="1" density="0" rgba="0.69804 0.69804 0.69804 1" mesh="Link_hip_l_pitch"/>
            <geom type="mesh" rgba="0.69804 0.69804 0.69804 1" mesh="Link_hip_l_pitch"/>
            <body name="Link_knee_l_pitch" pos="0 0.01125 -0.4" quat="0.921061 0 0.389418 0">
              <inertial pos="-0.0096425 -2.8684e-06 -0.13601" quat="0.762609 -0.016566 -0.000146223 0.646648" mass="2.9775" diaginertia="0.024206 0.0238598 0.00228447"/>
              <joint name="J_knee_l_pitch" pos="0 0 0" axis="0 -1 0" range="-2.35619 0.08727"/>
              <geom type="mesh" contype="0" conaffinity="0" group="1" density="0" rgba="0.66667 0.69804 0.76863 1" mesh="Link_knee_l_pitch"/>
              <geom type="mesh" rgba="0.66667 0.69804 0.76863 1" mesh="Link_knee_l_pitch"/>
              <body name="Link_ankle_l_pitch" pos="0 0 -0.387" quat="0.980067 0 -0.198669 0">
                <inertial pos="-6.1835e-12 1.2655e-07 6.7022e-08" quat="0.707107 0.707107 0 0" mass="0.10145" diaginertia="2.7175e-05 2.6565e-05 6.1118e-06"/>
                <joint name="J_ankle_l_pitch" pos="0 0 0" axis="0 -1 0" range="-0.47 0.87"/>
                <geom type="mesh" contype="0" conaffinity="0" group="1" density="0" rgba="0.52941 0.54902 0.54902 1" mesh="Link_ankle_l_pitch"/>
                <geom type="mesh" rgba="0.52941 0.54902 0.54902 1" mesh="Link_ankle_l_pitch"/>
                <body name="Link_ankle_l_roll">
                  <inertial pos="0.041077 -2.9318e-08 -0.043909" quat="0 0.735951 0 0.677035" mass="0.752288" diaginertia="0.00365937 0.0036465 0.000416828"/>
                  <joint name="J_ankle_l_roll" pos="0 0 0" axis="1 0 0" range="-0.43633 0.43633"/>
                  <geom type="mesh" contype="0" conaffinity="0" group="1" density="0" rgba="0.89804 0.91765 0.92941 1" mesh="Link_ankle_l_roll"/>
                  <geom type="mesh" rgba="0.89804 0.91765 0.92941 1" mesh="Link_ankle_l_roll"/>
                </body>
              </body>
            </body>
          </body>
        </body>
      </body>
    </body>
  </worldbody>
</mujoco>
