<?xml version='1.0' encoding='UTF-8'?>
<mujoco model="Hua">
  <compiler angle="radian"/>
  <default>
    <joint limited="true" damping="0.1" armature="0.005"/>
    <motor ctrllimited="true"/>
    <geom contype="1" conaffinity="1" condim="4" solref="0.001 2" friction="0.9 0.2 0.2"/>
    <equality solref="0.001 2"/>
  </default>
  <asset>
    <mesh name="base_link" file="../meshes/base_link.STL"/>
    <mesh name="waist_yaw_link" file="../meshes/waist_yaw_link.STL"/>
    <mesh name="qhy" file="../meshes/qhy.STL"/>
    <mesh name="zyy" file="../meshes/zyy.STL"/>
    <mesh name="bz" file="../meshes/bz.STL"/>
    <mesh name="left_shoulder_pitch" file="../meshes/left_shoulder_pitch.STL"/>
    <mesh name="left_shoulder_roll" file="../meshes/left_shoulder_roll.STL"/>
    <mesh name="left_shoulder_yaw" file="../meshes/left_shoulder_yaw.STL"/>
    <mesh name="left_elbow_pitch" file="../meshes/left_elbow_pitch.STL"/>
    <mesh name="left_elbow_yaw" file="../meshes/left_elbow_yaw.STL"/>
    <mesh name="left_wrist_roll" file="../meshes/left_wrist_roll.STL"/>
    <mesh name="right_shoulder_pitch" file="../meshes/right_shoulder_pitch.STL"/>
    <mesh name="right_shoulder_roll" file="../meshes/right_shoulder_roll.STL"/>
    <mesh name="right_shoulder_yaw" file="../meshes/right_shoulder_yaw.STL"/>
    <mesh name="right_elbow_pitch" file="../meshes/right_elbow_pitch.STL"/>
    <mesh name="right_elbow_yaw" file="../meshes/right_elbow_yaw.STL"/>
    <mesh name="right_wrist_roll" file="../meshes/right_wrist_roll.STL"/>
    <mesh name="left_leg_roll" file="../meshes/left_leg_roll.STL"/>
    <mesh name="left_leg_pitch" file="../meshes/left_leg_pitch.STL"/>
    <mesh name="left_leg_yaw" file="../meshes/left_leg_yaw.STL"/>
    <mesh name="left_knee" file="../meshes/left_knee.STL"/>
    <mesh name="left_ankle_pitch" file="../meshes/left_ankle_pitch.STL"/>
    <mesh name="left_ankle_roll" file="../meshes/left_ankle_roll.STL"/>
    <mesh name="right_leg_roll" file="../meshes/right_leg_roll.STL"/>
    <mesh name="right_leg_pitch" file="../meshes/right_leg_pitch.STL"/>
    <mesh name="right_leg_yaw" file="../meshes/right_leg_yaw.STL"/>
    <mesh name="right_knee" file="../meshes/right_knee.STL"/>
    <mesh name="right_ankle_pitch" file="../meshes/right_ankle_pitch.STL"/>
    <mesh name="right_ankle_roll" file="../meshes/right_ankle_roll.STL"/>
  </asset>
  <worldbody>
    <body name="base_link" pos="0 0 0.70">
      <inertial pos="-1.59722e-05 -0.0309005 -0.00831414" quat="-0.209597 0.675323 -0.209475 0.675372" mass="0.267" diaginertia="0.00407274 0.00287424 0.00174168"/>
      <joint name="floating_base_joint" type="free" limited="false" />
      <site name="imu" size="0.01" pos="0 0 0"/>
      <geom type="mesh"  group="1" density="0" rgba="0.898039 0.917647 0.929412 1" mesh="base_link"/>
      <geom size="0.1 0.075 0.075" type="box" rgba="0.898039 0.917647 0.929412 1"/>
      <body name="waist_yaw_link" pos="0 -0.00158447 -0.07">
        <inertial pos="-6.88174e-09 -0.0189296 0.0180205" quat="0.566981 0.422531 -0.422562 0.566958" mass="4.39" diaginertia="0.000503893 0.000303946 0.000262054"/>
        <geom type="mesh"  group="1" density="0" rgba="0.890196 0.890196 0.913725 1" mesh="waist_yaw_link"/>
        <body name="left_leg_roll" pos="-0.09 -0.077067 -0.058796" quat="0.0922928 -0.701057 -0.560988 0.430458">
          <inertial pos="0.0324159 0.0139032 -0.0139032" quat="0.504051 0.208537 0.773965 0.321595" mass="1.731" diaginertia="0.000723896 0.000521121 0.000361144"/>
          <joint name="left_leg_roll_joint" pos="0 0 0" axis="1 0 0" limited="true" range="-3.14 3.14" />
          <geom type="mesh"  group="1" density="0" rgba="0.898039 0.917647 0.929412 1" mesh="left_leg_roll"/>
          <geom type="mesh" rgba="0.898039 0.917647 0.929412 1" mesh="left_leg_roll"/>
          <body name="left_leg_pitch" pos="0.076 0.0247487 -0.0247487" quat="0.0840177 -0.702098 -0.437049 0.555867">
            <inertial pos="-0.00443165 0 -0.0324759" quat="0.972882 0 0.231303 0" mass="0.303" diaginertia="0.00042645 0.000400261 0.00015117"/>
            <joint name="left_leg_pitch_joint" pos="0 0 0" axis="1 0 0" limited="true" range="-3.14 3.14" />
            <geom type="mesh"  group="1" density="0" rgba="0.898039 0.917647 0.929412 1" mesh="left_leg_pitch"/>
            <geom type="mesh" rgba="0.898039 0.917647 0.929412 1" mesh="left_leg_pitch"/>
            <body name="left_leg_yaw" pos="-0.024 0 -0.0702">
              <inertial pos="0.00209246 -1.18292e-05 -0.0769962" quat="0.985722 0.00171262 -0.168371 -0.00105539" mass="2.305" diaginertia="0.00124557 0.00104095 0.000987464"/>
              <joint name="left_leg_yaw_joint" pos="0 0 0" axis="0 0 1" limited="true" range="-3.14 3.14" />
              <geom type="mesh"  group="1" density="0" rgba="0.898039 0.917647 0.929412 1" mesh="left_leg_yaw"/>
              <geom type="mesh" rgba="0.898039 0.917647 0.929412 1" mesh="left_leg_yaw"/>
              <body name="left_knee" pos="0.0188 0 -0.1358" quat="0.921061 -0.389418 0 0">
                <inertial pos="-0.0248024 0.00815811 -0.128165" quat="0.484132 0.0629019 0.0397663 0.871825" mass="1.363" diaginertia="0.00427627 0.00426862 0.000577312"/>
                <joint name="left_knee_joint" pos="0 0 0" axis="-1 0 0" limited="true" range="-3.14 3.14" />
                <geom type="mesh"  group="1" density="0" rgba="0.792157 0.819608 0.933333 1" mesh="left_knee"/>
                <geom type="cylinder" size="0.03 0.11" pos="-0.025 0 -0.17" rgba="0.792157 0.819608 0.933333 1"/>
                <body name="left_ankle_pitch" pos="-0.0299 0 -0.30494" quat="0.988771 0.149438 0 0">
                  <inertial pos="0 0 0" quat="0 0.707107 0 0.707107" mass="0.078" diaginertia="1.38009e-05 9.46456e-06 6.37474e-06"/>
                  <joint name="left_ankle_pitch_joint" pos="0 0 0" axis="1 0 0" limited="true" range="-3.14 3.14" />
                  <geom type="mesh"  group="1" density="0" rgba="0.698039 0.698039 0.698039 1" mesh="left_ankle_pitch"/>
                  <geom type="mesh" rgba="0.698039 0.698039 0.698039 1" mesh="left_ankle_pitch"/>
                  <body name="left_ankle_roll">
                    <inertial pos="-2.64121e-06 0.0010869 -0.0249324" quat="0.500466 0.499535 -0.499464 0.500534" mass="0.365" diaginertia="0.00175049 0.0011904 0.000599014"/>
                    <joint name="left_ankle_roll_joint" pos="0 0 0" axis="0 -1 0" limited="true" range="-3.14 3.14" />
                    <geom type="mesh" group="1" density="0" rgba="0.898039 0.917647 0.929412 1" mesh="left_ankle_roll"/>
                    
                   <geom name="left_foot1" type="cylinder" size="0.01" fromto="-0.045 0.07 -0.03 -0.045 -0.07 -0.03" rgba=".2 .6 .2 .3" contype="1" conaffinity="1"/>
                   <geom name="left_foot2" type="cylinder" size="0.01" fromto="-0.030 0.0875 -0.03 -0.030 -0.0875 -0.03" rgba=".2 .6 .2 .3" contype="1" conaffinity="1"/>
                   <geom name="left_foot3" type="cylinder" size="0.01" fromto="-0.015 0.095 -0.03 -0.015 -0.095 -0.03" rgba=".2 .6 .2 .3" contype="1" conaffinity="1"/>
                   <geom name="left_foot4" type="cylinder" size="0.01" fromto="0.000 0.095 -0.03 0.000 -0.095 -0.03" rgba=".2 .6 .2 .3" contype="1" conaffinity="1"/>
                   <geom name="left_foot5" type="cylinder" size="0.01" fromto="0.015 0.095 -0.03 0.015 -0.095 -0.03" rgba=".2 .6 .2 .3" contype="1" conaffinity="1"/>
                   <geom name="left_foot6" type="cylinder" size="0.01" fromto="0.030 0.0875 -0.03 0.030 -0.0875 -0.03" rgba=".2 .6 .2 .3" contype="1" conaffinity="1"/>
                   <geom name="left_foot7" type="cylinder" size="0.01" fromto="0.045 0.07 -0.03 0.045 -0.07 -0.03" rgba=".2 .6 .2 .3" contype="1" conaffinity="1"/>
                  </body>
                </body>
              </body>
            </body>
          </body>
        </body>
        <body name="right_leg_roll" pos="0.09 -0.0770665 -0.0587965" quat="0.092296 -0.701057 -0.560986 0.430459">
          <inertial pos="0.0324159 -0.0139032 0.0139032" quat="0.773965 0.321595 0.504051 0.208537" mass="1.731" diaginertia="0.000723896 0.000521121 0.000361144"/>
          <joint name="right_leg_roll_joint" pos="0 0 0" axis="1 0 0" limited="true" range="-3.14 3.14" />
          <geom type="mesh"  group="1" density="0" rgba="0.898039 0.917647 0.929412 1" mesh="right_leg_roll"/>
          <geom type="mesh" rgba="0.898039 0.917647 0.929412 1" mesh="right_leg_roll"/>
          <body name="right_leg_pitch" pos="0.076 -0.0247487 0.0247487" quat="0.0840177 -0.702098 -0.437049 0.555867">
            <inertial pos="0.00443165 0 -0.0324759" quat="0.972882 0 -0.231303 0" mass="0.303" diaginertia="0.00042645 0.000400261 0.00015117"/>
            <joint name="right_leg_pitch_joint" pos="0 0 0" axis="-1 0 0" limited="true" range="-3.14 3.14" />
            <geom type="mesh"  group="1" density="0" rgba="0.898039 0.917647 0.929412 1" mesh="right_leg_pitch"/>
            <geom type="mesh" rgba="0.898039 0.917647 0.929412 1" mesh="right_leg_pitch"/>
            <body name="right_leg_yaw" pos="0.024 0 -0.0702">
              <inertial pos="-0.00212718 5.36892e-08 -0.0769928" quat="0.985484 -0.00329064 0.169737 -3.74264e-05" mass="2.305" diaginertia="0.00124615 0.00104097 0.000986858"/>
              <joint name="right_leg_yaw_joint" pos="0 0 0" axis="0 0 1" limited="true" range="-3.14 3.14" />
              <geom type="mesh"  group="1" density="0" rgba="0.898039 0.917647 0.929412 1" mesh="right_leg_yaw"/>
              <geom type="mesh" rgba="0.898039 0.917647 0.929412 1" mesh="right_leg_yaw"/>
              <body name="right_knee" pos="-0.0188 0 -0.1358" quat="0.921061 -0.389418 0 0">
                <inertial pos="0.0242687 0.0081581 -0.128279" quat="0.909672 -0.0341927 -0.065955 0.408628" mass="1.363" diaginertia="0.00428812 0.00425639 0.000577718"/>
                <joint name="right_knee_joint" pos="0 0 0" axis="1 0 0" limited="true" range="-3.14 3.14" />
                <geom type="mesh"  group="1" density="0" rgba="0.792157 0.819608 0.933333 1" mesh="right_knee"/>
                <geom type="cylinder" size="0.03 0.11" pos="0.025 0 -0.17" rgba="0.792157 0.819608 0.933333 1"/>
                <body name="right_ankle_pitch" pos="0.0299 0 -0.30494" quat="0.988771 0.149438 0 0">
                  <inertial pos="0 0 0" quat="0 0.707107 0 0.707107" mass="0.078" diaginertia="1.38009e-05 9.46456e-06 6.37474e-06"/>
                  <joint name="right_ankle_pitch_joint" pos="0 0 0" axis="1 0 0" limited="true" range="-3.14 3.14" />
                  <geom type="mesh"  group="1" density="0" rgba="0.698039 0.698039 0.698039 1" mesh="right_ankle_pitch"/>
                  <geom type="mesh" rgba="0.698039 0.698039 0.698039 1" mesh="right_ankle_pitch"/>
                  <body name="right_ankle_roll">
                    <inertial pos="-2.64357e-06 0.0010869 -0.0249324" quat="0.500466 0.499535 -0.499464 0.500534" mass="0.365" diaginertia="0.00175049 0.0011904 0.000599014"/>
                    <joint name="right_ankle_roll_joint" pos="0 0 0" axis="0 -1 0" limited="true" range="-3.14 3.14" />
                    <geom type="mesh" group="1" density="0" rgba="0.898039 0.917647 0.929412 1" mesh="right_ankle_roll"/>
                    
                    <geom name="right_foot1" type="cylinder" size="0.01" fromto="-0.045 0.07 -0.03 -0.045 -0.07 -0.03" rgba=".2 .6 .2 .3" contype="1" conaffinity="1"/>
                    <geom name="right_foot2" type="cylinder" size="0.01" fromto="-0.030 0.0875 -0.03 -0.030 -0.0875 -0.03" rgba=".2 .6 .2 .3" contype="1" conaffinity="1"/>
                    <geom name="right_foot3" type="cylinder" size="0.01" fromto="-0.015 0.095 -0.03 -0.015 -0.095 -0.03" rgba=".2 .6 .2 .3" contype="1" conaffinity="1"/>
                    <geom name="right_foot4" type="cylinder" size="0.01" fromto="0.000 0.095 -0.03 0.000 -0.095 -0.03" rgba=".2 .6 .2 .3" contype="1" conaffinity="1"/>
                    <geom name="right_foot5" type="cylinder" size="0.01" fromto="0.015 0.095 -0.03 0.015 -0.095 -0.03" rgba=".2 .6 .2 .3" contype="1" conaffinity="1"/>
                    <geom name="right_foot6" type="cylinder" size="0.01" fromto="0.030 0.0875 -0.03 0.030 -0.0875 -0.03" rgba=".2 .6 .2 .3" contype="1" conaffinity="1"/>
                    <geom name="right_foot7" type="cylinder" size="0.01" fromto="0.045 0.07 -0.03 0.045 -0.07 -0.03" rgba=".2 .6 .2 .3" contype="1" conaffinity="1"/>
                  </body>
                </body>
              </body>
            </body>
          </body>
        </body>
      </body>
      <body name="qhy" pos="0 0 0.0392">
        <inertial pos="0 0 0" quat="0 0.707107 0 0.707107" mass="0.078" diaginertia="1.4299e-05 9.96263e-06 7.3639e-06"/>
        <geom type="mesh"  group="1" density="0" rgba="0.698039 0.698039 0.698039 1" mesh="qhy"/>
        <body name="zyy">
          <inertial pos="-1.15039e-05 7.71994e-05 0.163828" quat="0.500075 0.499924 0.500071 0.499931" mass="5.651" diaginertia="0.0357037 0.0347078 0.0117287"/>
          <geom type="mesh"  group="1" density="0" rgba="0.898039 0.917647 0.929412 1" mesh="zyy"/>
          <body name="bz" pos="0 0 0.2485">
            <inertial pos="0.000351178 -5.3447e-05 0.0783478" quat="-0.0732317 0.704006 -0.0611029 0.703761" mass="0.479" diaginertia="0.000349843 0.000346996 0.000308488"/>
            <geom type="mesh"  group="1" density="0" rgba="0.317647 0.247059 0.207843 1" mesh="bz"/>
          </body>
          <body name="left_shoulder_pitch" pos="-0.123 0 0.215">
            <inertial pos="-0.0459473 -0.0074277 0.0002732" quat="0.509225 0.480501 0.514991 0.494564" mass="0.63" diaginertia="0.000590193 0.000494392 0.000430539"/>
            <geom type="mesh"  group="1" density="0" rgba="0.317647 0.247059 0.207843 1" mesh="left_shoulder_pitch"/>
            <body name="left_shoulder_roll" pos="-0.064 -0.036 0">
              <inertial pos="0.000273234 0.0175784 -0.0501061" quat="0.671759 0.173207 -0.164172 0.701275" mass="0.708" diaginertia="0.0008956 0.0008317 0.000601913"/>
              <geom type="mesh"  group="1" density="0" rgba="0.317647 0.247059 0.207843 1" mesh="left_shoulder_roll"/>
              <body name="left_shoulder_yaw" pos="0 0.036 -0.098">
                <inertial pos="-0.0344995 0 -0.0307905" quat="0.927931 0 0.372752 0" mass="0.257" diaginertia="0.00103406 0.00101575 0.000406407"/>
                <geom type="mesh"  group="1" density="0" rgba="0.317647 0.247059 0.207843 1" mesh="left_shoulder_yaw"/>
                <body name="left_elbow_pitch" pos="-0.046 0 -0.066">
                  <inertial pos="0.024772 -0.00040515 -0.012387" quat="0.989428 -0.0118793 -0.135159 0.0512141" mass="0.54" diaginertia="0.000505042 0.000451908 0.000320817"/>
                  <geom type="mesh"  group="1" density="0" rgba="0.898039 0.917647 0.929412 1" mesh="left_elbow_pitch"/>
                  <body name="left_elbow_yaw" pos="0.043 0 -0.0665">
                    <inertial pos="0.00332449 5.4661e-09 -0.0538434" quat="1 0.000189023 3.3057e-08 0.000174884" mass="0.881" diaginertia="0.000616163 0.000448888 0.000294155"/>
                    <geom type="mesh"  group="1" density="0" rgba="0.898039 0.917647 0.929412 1" mesh="left_elbow_yaw"/>
                    <body name="left_wrist_roll" pos="0.016 0 -0.0962296">
                      <inertial pos="0.00266678 0 -0.0255271" quat="0.977636 0 0.210303 0" mass="0.188" diaginertia="0.000619905 0.000564957 0.000299097"/>
                      <geom type="mesh"  group="1" density="0" rgba="0.317647 0.247059 0.207843 1" mesh="left_wrist_roll"/>
                    </body>
                  </body>
                </body>
              </body>
            </body>
          </body>
          <body name="right_shoulder_pitch" pos="0.123 0 0.215">
            <inertial pos="0.046005 -0.00742767 0.000306515" quat="0.514071 0.493402 0.512153 0.479567" mass="0.63" diaginertia="0.000590209 0.000494806 0.000430109"/>
            <geom type="mesh"  group="1" density="0" rgba="0.317647 0.247059 0.207843 1" mesh="right_shoulder_pitch"/>
            <body name="right_shoulder_roll" pos="0.064 -0.036 0">
              <inertial pos="-0.000273234 0.0175241 -0.0501061" quat="0.703361 0.165639 -0.172731 0.669336" mass="0.708" diaginertia="0.000896251 0.000831652 0.000601311"/>
              <geom type="mesh"  group="1" density="0" rgba="0.317647 0.247059 0.207843 1" mesh="right_shoulder_roll"/>
              <body name="right_shoulder_yaw" pos="0 0.036 -0.098">
                <inertial pos="0.0344995 0 -0.0307905" quat="0.927931 0 -0.372752 0" mass="0.257" diaginertia="0.00103406 0.00101575 0.000406407"/>
                <geom type="mesh"  group="1" density="0" rgba="0.317647 0.247059 0.207843 1" mesh="right_shoulder_yaw"/>
                <body name="right_elbow_pitch" pos="0.046 0 -0.066">
                  <inertial pos="-0.024772 -0.00040515 -0.0123064" quat="0.989701 -0.0135047 0.133395 -0.0501513" mass="0.54" diaginertia="0.000504635 0.000451942 0.00032119"/>
                  <geom type="mesh"  group="1" density="0" rgba="0.898039 0.917647 0.929412 1" mesh="right_elbow_pitch"/>
                  <body name="right_elbow_yaw" pos="-0.043 0 -0.0665">
                    <inertial pos="-0.00332449 5.40529e-09 -0.0538434" quat="1 -0.000188868 -3.30299e-08 0.000174884" mass="0.881" diaginertia="0.000616163 0.000448888 0.000294155"/>
                    <geom type="mesh"  group="1" density="0" rgba="0.898039 0.917647 0.929412 1" mesh="right_elbow_yaw"/>
                    <body name="right_wrist_roll" pos="-0.016 0 -0.0962296" quat="0 0 1 0">
                      <inertial pos="0.00266678 3.07582e-11 0.0255271" quat="0.977636 0 -0.210303 0" mass="0.188" diaginertia="0.000619905 0.000564957 0.000299097"/>
                      <geom type="mesh"  group="1" density="0" rgba="0.317647 0.247059 0.207843 1" mesh="right_wrist_roll"/>
                    </body>
                  </body>
                </body>
              </body>
            </body>
          </body>
        </body>
      </body>
    </body>
  </worldbody>
  <actuator>
    <motor name="left_leg_roll"     joint="left_leg_roll_joint"     gear="1" ctrllimited="true" ctrlrange="-300 300"/>
    <motor name="left_leg_pitch"    joint="left_leg_pitch_joint"    gear="1" ctrllimited="true" ctrlrange="-300 300"/>
    <motor name="left_leg_yaw"      joint="left_leg_yaw_joint"      gear="1" ctrllimited="true" ctrlrange="-300 300"/>
    <motor name="left_knee"         joint="left_knee_joint"         gear="1" ctrllimited="true" ctrlrange="-300 300"/>
    <motor name="left_ankle_pitch"  joint="left_ankle_pitch_joint"  gear="1" ctrllimited="true" ctrlrange="-300 300"/>
    <motor name="left_ankle_roll"   joint="left_ankle_roll_joint"   gear="1" ctrllimited="true" ctrlrange="-300 300"/>
    
    <motor name="right_leg_roll"    joint="right_leg_roll_joint"    gear="1" ctrllimited="true" ctrlrange="-300 300"/>
    <motor name="right_leg_pitch"   joint="right_leg_pitch_joint"   gear="1" ctrllimited="true" ctrlrange="-300 300"/>
    <motor name="right_leg_yaw"     joint="right_leg_yaw_joint"     gear="1" ctrllimited="true" ctrlrange="-300 300"/>
    <motor name="right_knee"        joint="right_knee_joint"        gear="1" ctrllimited="true" ctrlrange="-300 300"/>
    <motor name="right_ankle_pitch" joint="right_ankle_pitch_joint" gear="1" ctrllimited="true" ctrlrange="-300 300"/>
    <motor name="right_ankle_roll"  joint="right_ankle_roll_joint"  gear="1" ctrllimited="true" ctrlrange="-300 300"/>
  </actuator>

  <sensor>
    <framequat     name="orientation"  objtype="site" objname="imu"/>
    <framepos      name="position"     objtype="site" objname="imu"/>
    <gyro          name="angular-velocity"         site="imu"/>
    <velocimeter   name="velocimeter"  site="imu"/>
    <accelerometer name="accelerometer" site="imu"/>
  </sensor>
  <contact>
  <exclude body1="left_ankle_roll" body2="left_ankle_pitch"/>
  <exclude body1="left_ankle_roll" body2="left_knee"/>
  <exclude body1="right_ankle_roll" body2="right_ankle_pitch"/>
  <exclude body1="right_ankle_roll" body2="right_knee"/>  
  <exclude body1="left_leg_roll" body2="base_link"/>
  <exclude body1="right_leg_roll" body2="base_link"/>
  <exclude body1="base_link" body2="waist_yaw_link"/>
  <exclude body1="base_link" body2="qhy"/>
  <exclude body1="qhy" body2="zyy"/>
  <exclude body1="zyy" body2="bz"/>
  <exclude body1="waist_yaw_link" body2="left_leg_roll"/>
  <exclude body1="left_leg_roll" body2="left_leg_pitch"/>
  <exclude body1="left_leg_pitch" body2="left_leg_yaw"/>
  <exclude body1="left_leg_yaw" body2="left_knee"/>
  <exclude body1="left_knee" body2="left_ankle_pitch"/>
  <exclude body1="left_ankle_pitch" body2="left_ankle_roll"/>
  <exclude body1="waist_yaw_link" body2="right_leg_roll"/>
  <exclude body1="right_leg_roll" body2="right_leg_pitch"/>
  <exclude body1="right_leg_pitch" body2="right_leg_yaw"/>
  <exclude body1="right_leg_yaw" body2="right_knee"/>
  <exclude body1="right_knee" body2="right_ankle_pitch"/>
  <exclude body1="right_ankle_pitch" body2="right_ankle_roll"/>
</contact>
</mujoco>